<?xml version="1.0"?>
<robot name="demo_arm" xmlns:xacro="http://wiki.ros.org/xacro">
    <!-- links: main serial chain -->
    <link name="base_link"/>
    <link name="link_1"/>
    <link name="link_2"/>
    <link name="link_3"/>
    <link name="link_4"/>
    <link name="link_5"/>
    <link name="link_6"/>

    <!-- joints: main serial chain -->
    <joint name="joint_1" type="revolute">
        <origin xyz="0 0 0.650" rpy="0 0 0"/>
        <parent link="base_link"/>
        <child link="link_1"/>
        <axis xyz="0 0 1"/>
        <limit lower="${radians(-180)}" upper="${radians(180)}" effort="0" velocity="${radians(205)}" />
    </joint>
    <joint name="joint_2" type="revolute">
        <origin xyz="0.075 0 0" rpy="0 0 0"/>
        <parent link="link_1"/>
        <child link="link_2"/>
        <axis xyz="0 1 0"/>
        <limit lower="${radians(-100)}" upper="${radians(140)}" effort="0" velocity="${radians(205)}" />
    </joint>
    <joint name="joint_3" type="revolute">
        <origin xyz="0 0 0.905" rpy="0 0 0"/>
        <parent link="link_2"/>
        <child link="link_3"/>
        <axis xyz="0 -1 0"/>
        <limit lower="${radians(-149)}" upper="${radians(320)}" effort="0" velocity="${radians(260)}" />
    </joint>
    <joint name="joint_4" type="revolute">
        <origin xyz="0 0 0.120" rpy="0 0 0"/>
        <parent link="link_3"/>
        <child link="link_4"/>
        <axis xyz="-1 0 0"/>
        <limit lower="${radians(-200)}" upper="${radians(200)}" effort="0" velocity="${radians(415)}" />
    </joint>
    <joint name="joint_5" type="revolute">
        <origin xyz="0.865 0 0" rpy="0 0 0"/>
        <parent link="link_4"/>
        <child link="link_5"/>
        <axis xyz="0 -1 0"/>
        <limit lower="${radians(-145)}" upper="${radians(145)}" effort="0" velocity="${radians(415)}" />
    </joint>
    <joint name="joint_6" type="revolute">
        <origin xyz="0.100 0 0" rpy="0 0 0"/>
        <parent link="link_5"/>
        <child link="link_6"/>
        <axis xyz="-1 0 0"/>
        <limit lower="${radians(-270)}" upper="${radians(270)}" effort="0" velocity="${radians(880)}" />
    </joint>

    <!-- ROS-Industrial 'base' frame: base_link to Fanuc World Coordinates transform -->
    <link name="base" />
    <joint name="base_link-base" type="fixed">
        <origin xyz="0 0 0.650" rpy="0 0 0"/>
        <parent link="base_link"/>
        <child link="base"/>
    </joint>

    <!-- ROS-Industrial 'flange' frame: attachment point for EEF models -->
    <link name="flange" />
    <joint name="joint_6-flange" type="fixed">
        <origin xyz="0 0 0" rpy="0 0 0" />
        <parent link="link_6" />
        <child link="flange" />
    </joint>

    <!-- ROS-Industrial 'tool0' frame: all-zeros tool frame -->
    <link name="tool0" />
    <joint name="link_6-tool0" type="fixed">
        <origin xyz="0 0 0" rpy="${pi} ${-pi/2.0} 0" />
        <parent link="flange" />
        <child link="tool0" />
    </joint>
</robot>
